[2024-12-24T17:51:29.627+0000] {local_task_job_runner.py:120} INFO - ::group::Pre task execution logs
[2024-12-24T17:51:29.661+0000] {taskinstance.py:2076} INFO - Dependencies all met for dep_context=non-requeueable deps ti=<TaskInstance: pipeline.push_data_in_postgres manual__2024-12-24T17:50:49.335943+00:00 [queued]>
[2024-12-24T17:51:29.670+0000] {taskinstance.py:2076} INFO - Dependencies all met for dep_context=requeueable deps ti=<TaskInstance: pipeline.push_data_in_postgres manual__2024-12-24T17:50:49.335943+00:00 [queued]>
[2024-12-24T17:51:29.670+0000] {taskinstance.py:2306} INFO - Starting attempt 1 of 1
[2024-12-24T17:51:29.685+0000] {taskinstance.py:2330} INFO - Executing <Task(_PythonDecoratedOperator): push_data_in_postgres> on 2024-12-24 17:50:49.335943+00:00
[2024-12-24T17:51:29.689+0000] {standard_task_runner.py:64} INFO - Started process 399 to run task
[2024-12-24T17:51:29.692+0000] {standard_task_runner.py:90} INFO - Running: ['***', 'tasks', 'run', 'pipeline', 'push_data_in_postgres', 'manual__2024-12-24T17:50:49.335943+00:00', '--job-id', '874', '--raw', '--subdir', 'DAGS_FOLDER/pipline.py', '--cfg-path', '/tmp/tmpjp6q5972']
[2024-12-24T17:51:29.694+0000] {standard_task_runner.py:91} INFO - Job 874: Subtask push_data_in_postgres
[2024-12-24T17:51:29.742+0000] {task_command.py:426} INFO - Running <TaskInstance: pipeline.push_data_in_postgres manual__2024-12-24T17:50:49.335943+00:00 [running]> on host cd39b53ebd5d
[2024-12-24T17:51:29.837+0000] {taskinstance.py:2648} INFO - Exporting env vars: AIRFLOW_CTX_DAG_OWNER='***' AIRFLOW_CTX_DAG_ID='pipeline' AIRFLOW_CTX_TASK_ID='push_data_in_postgres' AIRFLOW_CTX_EXECUTION_DATE='2024-12-24T17:50:49.335943+00:00' AIRFLOW_CTX_TRY_NUMBER='1' AIRFLOW_CTX_DAG_RUN_ID='manual__2024-12-24T17:50:49.335943+00:00'
[2024-12-24T17:51:29.838+0000] {taskinstance.py:430} INFO - ::endgroup::
[2024-12-24T17:51:29.846+0000] {base.py:84} INFO - Using connection ID 'postgres_default_2' for task execution.
[2024-12-24T17:51:31.097+0000] {logging_mixin.py:188} INFO - Erreur de connexion Ã  PostgreSQL : relation "journal" does not exist
LINE 1: SELECT * FROM journal;
                      ^
[2024-12-24T17:51:31.098+0000] {python.py:237} INFO - Done. Returned value was: None
[2024-12-24T17:51:31.099+0000] {taskinstance.py:441} INFO - ::group::Post task execution logs
[2024-12-24T17:51:31.108+0000] {taskinstance.py:1206} INFO - Marking task as SUCCESS. dag_id=pipeline, task_id=push_data_in_postgres, run_id=manual__2024-12-24T17:50:49.335943+00:00, execution_date=20241224T175049, start_date=20241224T175129, end_date=20241224T175131
[2024-12-24T17:51:31.149+0000] {local_task_job_runner.py:243} INFO - Task exited with return code 0
[2024-12-24T17:51:31.169+0000] {taskinstance.py:3503} INFO - 0 downstream tasks scheduled from follow-on schedule check
[2024-12-24T17:51:31.181+0000] {local_task_job_runner.py:222} INFO - ::endgroup::
