[2024-12-25T00:27:15.615+0000] {local_task_job_runner.py:120} INFO - ::group::Pre task execution logs
[2024-12-25T00:27:15.666+0000] {taskinstance.py:2076} INFO - Dependencies all met for dep_context=non-requeueable deps ti=<TaskInstance: pipeline.insert_data_into_data_warehouse manual__2024-12-25T00:26:34.938198+00:00 [queued]>
[2024-12-25T00:27:15.679+0000] {taskinstance.py:2076} INFO - Dependencies all met for dep_context=requeueable deps ti=<TaskInstance: pipeline.insert_data_into_data_warehouse manual__2024-12-25T00:26:34.938198+00:00 [queued]>
[2024-12-25T00:27:15.682+0000] {taskinstance.py:2306} INFO - Starting attempt 1 of 1
[2024-12-25T00:27:15.702+0000] {taskinstance.py:2330} INFO - Executing <Task(_PythonDecoratedOperator): insert_data_into_data_warehouse> on 2024-12-25 00:26:34.938198+00:00
[2024-12-25T00:27:15.709+0000] {standard_task_runner.py:64} INFO - Started process 1171 to run task
[2024-12-25T00:27:15.712+0000] {standard_task_runner.py:90} INFO - Running: ['***', 'tasks', 'run', 'pipeline', 'insert_data_into_data_warehouse', 'manual__2024-12-25T00:26:34.938198+00:00', '--job-id', '947', '--raw', '--subdir', 'DAGS_FOLDER/pipline.py', '--cfg-path', '/tmp/tmp5jr2p3ar']
[2024-12-25T00:27:15.715+0000] {standard_task_runner.py:91} INFO - Job 947: Subtask insert_data_into_data_warehouse
[2024-12-25T00:27:15.776+0000] {task_command.py:426} INFO - Running <TaskInstance: pipeline.insert_data_into_data_warehouse manual__2024-12-25T00:26:34.938198+00:00 [running]> on host 2aedf3b64bae
[2024-12-25T00:27:15.923+0000] {taskinstance.py:2648} INFO - Exporting env vars: AIRFLOW_CTX_DAG_OWNER='***' AIRFLOW_CTX_DAG_ID='pipeline' AIRFLOW_CTX_TASK_ID='insert_data_into_data_warehouse' AIRFLOW_CTX_EXECUTION_DATE='2024-12-25T00:26:34.938198+00:00' AIRFLOW_CTX_TRY_NUMBER='1' AIRFLOW_CTX_DAG_RUN_ID='manual__2024-12-25T00:26:34.938198+00:00'
[2024-12-25T00:27:15.925+0000] {taskinstance.py:430} INFO - ::endgroup::
[2024-12-25T00:27:15.926+0000] {logging_mixin.py:188} INFO - None
[2024-12-25T00:27:15.927+0000] {taskinstance.py:441} INFO - ::group::Post task execution logs
[2024-12-25T00:27:15.928+0000] {taskinstance.py:2905} ERROR - Task failed with exception
Traceback (most recent call last):
  File "/home/airflow/.local/lib/python3.11/site-packages/airflow/models/taskinstance.py", line 465, in _execute_task
    result = _execute_callable(context=context, **execute_callable_kwargs)
             ^^^^^^^^^^^^^^^^^^^^^^^^^^^^^^^^^^^^^^^^^^^^^^^^^^^^^^^^^^^^^
  File "/home/airflow/.local/lib/python3.11/site-packages/airflow/models/taskinstance.py", line 432, in _execute_callable
    return execute_callable(context=context, **execute_callable_kwargs)
           ^^^^^^^^^^^^^^^^^^^^^^^^^^^^^^^^^^^^^^^^^^^^^^^^^^^^^^^^^^^^
  File "/home/airflow/.local/lib/python3.11/site-packages/airflow/models/baseoperator.py", line 401, in wrapper
    return func(self, *args, **kwargs)
           ^^^^^^^^^^^^^^^^^^^^^^^^^^^
  File "/home/airflow/.local/lib/python3.11/site-packages/airflow/decorators/base.py", line 265, in execute
    return_value = super().execute(context)
                   ^^^^^^^^^^^^^^^^^^^^^^^^
  File "/home/airflow/.local/lib/python3.11/site-packages/airflow/models/baseoperator.py", line 401, in wrapper
    return func(self, *args, **kwargs)
           ^^^^^^^^^^^^^^^^^^^^^^^^^^^
  File "/home/airflow/.local/lib/python3.11/site-packages/airflow/operators/python.py", line 235, in execute
    return_value = self.execute_callable()
                   ^^^^^^^^^^^^^^^^^^^^^^^
  File "/home/airflow/.local/lib/python3.11/site-packages/airflow/operators/python.py", line 252, in execute_callable
    return self.python_callable(*self.op_args, **self.op_kwargs)
           ^^^^^^^^^^^^^^^^^^^^^^^^^^^^^^^^^^^^^^^^^^^^^^^^^^^^^
  File "/opt/airflow/dags/pipline.py", line 361, in insert_data_into_data_warehouse
    data = verify_and_convert_structure(data)
           ^^^^^^^^^^^^^^^^^^^^^^^^^^^^^^^^^^
  File "/opt/airflow/dags/pipline.py", line 339, in verify_and_convert_structure
    for item in t:
TypeError: 'NoneType' object is not iterable
[2024-12-25T00:27:15.943+0000] {taskinstance.py:1206} INFO - Marking task as FAILED. dag_id=pipeline, task_id=insert_data_into_data_warehouse, run_id=manual__2024-12-25T00:26:34.938198+00:00, execution_date=20241225T002634, start_date=20241225T002715, end_date=20241225T002715
[2024-12-25T00:27:15.956+0000] {standard_task_runner.py:110} ERROR - Failed to execute job 947 for task insert_data_into_data_warehouse ('NoneType' object is not iterable; 1171)
[2024-12-25T00:27:15.965+0000] {local_task_job_runner.py:243} INFO - Task exited with return code 1
[2024-12-25T00:27:15.987+0000] {taskinstance.py:3503} INFO - 0 downstream tasks scheduled from follow-on schedule check
[2024-12-25T00:27:15.990+0000] {local_task_job_runner.py:222} INFO - ::endgroup::
