[2024-11-10T19:16:44.164+0000] {local_task_job_runner.py:120} INFO - ::group::Pre task execution logs
[2024-11-10T19:16:44.187+0000] {taskinstance.py:2076} INFO - Dependencies all met for dep_context=non-requeueable deps ti=<TaskInstance: pipeline.insert_data_into_data_warehouse__1 manual__2024-11-10T19:16:33.439795+00:00 [queued]>
[2024-11-10T19:16:44.196+0000] {taskinstance.py:2076} INFO - Dependencies all met for dep_context=requeueable deps ti=<TaskInstance: pipeline.insert_data_into_data_warehouse__1 manual__2024-11-10T19:16:33.439795+00:00 [queued]>
[2024-11-10T19:16:44.197+0000] {taskinstance.py:2306} INFO - Starting attempt 1 of 1
[2024-11-10T19:16:44.209+0000] {taskinstance.py:2330} INFO - Executing <Task(_PythonDecoratedOperator): insert_data_into_data_warehouse__1> on 2024-11-10 19:16:33.439795+00:00
[2024-11-10T19:16:44.212+0000] {standard_task_runner.py:64} INFO - Started process 225 to run task
[2024-11-10T19:16:44.215+0000] {standard_task_runner.py:90} INFO - Running: ['***', 'tasks', 'run', 'pipeline', 'insert_data_into_data_warehouse__1', 'manual__2024-11-10T19:16:33.439795+00:00', '--job-id', '596', '--raw', '--subdir', 'DAGS_FOLDER/pipline.py', '--cfg-path', '/tmp/tmpfg4s0awn']
[2024-11-10T19:16:44.217+0000] {standard_task_runner.py:91} INFO - Job 596: Subtask insert_data_into_data_warehouse__1
[2024-11-10T19:16:44.256+0000] {task_command.py:426} INFO - Running <TaskInstance: pipeline.insert_data_into_data_warehouse__1 manual__2024-11-10T19:16:33.439795+00:00 [running]> on host 838629e5723f
[2024-11-10T19:16:44.361+0000] {taskinstance.py:2648} INFO - Exporting env vars: AIRFLOW_CTX_DAG_OWNER='***' AIRFLOW_CTX_DAG_ID='pipeline' AIRFLOW_CTX_TASK_ID='insert_data_into_data_warehouse__1' AIRFLOW_CTX_EXECUTION_DATE='2024-11-10T19:16:33.439795+00:00' AIRFLOW_CTX_TRY_NUMBER='1' AIRFLOW_CTX_DAG_RUN_ID='manual__2024-11-10T19:16:33.439795+00:00'
[2024-11-10T19:16:44.362+0000] {taskinstance.py:430} INFO - ::endgroup::
[2024-11-10T19:16:44.363+0000] {taskinstance.py:441} INFO - ::group::Post task execution logs
[2024-11-10T19:16:44.364+0000] {taskinstance.py:2905} ERROR - Task failed with exception
Traceback (most recent call last):
  File "/opt/airflow/dags/pipline.py", line 283, in insert_data_into_data_warehouse
    journal_main = extract_journal_name(entry.get('journal_main', ''))
                                       ^^^^^^^^^
AttributeError: 'list' object has no attribute 'get'

During handling of the above exception, another exception occurred:

Traceback (most recent call last):
  File "/home/airflow/.local/lib/python3.11/site-packages/airflow/models/taskinstance.py", line 465, in _execute_task
    result = _execute_callable(context=context, **execute_callable_kwargs)
             ^^^^^^^^^^^^^^^^^^^^^^^^^^^^^^^^^^^^^^^^^^^^^^^^^^^^^^^^^^^^^
  File "/home/airflow/.local/lib/python3.11/site-packages/airflow/models/taskinstance.py", line 432, in _execute_callable
    return execute_callable(context=context, **execute_callable_kwargs)
           ^^^^^^^^^^^^^^^^^^^^^^^^^^^^^^^^^^^^^^^^^^^^^^^^^^^^^^^^^^^^
  File "/home/airflow/.local/lib/python3.11/site-packages/airflow/models/baseoperator.py", line 401, in wrapper
    return func(self, *args, **kwargs)
           ^^^^^^^^^^^^^^^^^^^^^^^^^^^
  File "/home/airflow/.local/lib/python3.11/site-packages/airflow/decorators/base.py", line 265, in execute
    return_value = super().execute(context)
                   ^^^^^^^^^^^^^^^^^^^^^^^^
  File "/home/airflow/.local/lib/python3.11/site-packages/airflow/models/baseoperator.py", line 401, in wrapper
    return func(self, *args, **kwargs)
           ^^^^^^^^^^^^^^^^^^^^^^^^^^^
  File "/home/airflow/.local/lib/python3.11/site-packages/airflow/operators/python.py", line 235, in execute
    return_value = self.execute_callable()
                   ^^^^^^^^^^^^^^^^^^^^^^^
  File "/home/airflow/.local/lib/python3.11/site-packages/airflow/operators/python.py", line 252, in execute_callable
    return self.python_callable(*self.op_args, **self.op_kwargs)
           ^^^^^^^^^^^^^^^^^^^^^^^^^^^^^^^^^^^^^^^^^^^^^^^^^^^^^
  File "/opt/airflow/dags/pipline.py", line 307, in insert_data_into_data_warehouse
    logging.error(f"Error processing publication '{entry.get('Title', '')}': {e}")
                                                   ^^^^^^^^^
AttributeError: 'list' object has no attribute 'get'
[2024-11-10T19:16:44.377+0000] {taskinstance.py:1206} INFO - Marking task as FAILED. dag_id=pipeline, task_id=insert_data_into_data_warehouse__1, run_id=manual__2024-11-10T19:16:33.439795+00:00, execution_date=20241110T191633, start_date=20241110T191644, end_date=20241110T191644
[2024-11-10T19:16:44.392+0000] {standard_task_runner.py:110} ERROR - Failed to execute job 596 for task insert_data_into_data_warehouse__1 ('list' object has no attribute 'get'; 225)
[2024-11-10T19:16:44.427+0000] {local_task_job_runner.py:243} INFO - Task exited with return code 1
[2024-11-10T19:16:44.441+0000] {taskinstance.py:3503} INFO - 0 downstream tasks scheduled from follow-on schedule check
[2024-11-10T19:16:44.443+0000] {local_task_job_runner.py:222} INFO - ::endgroup::
