[2024-12-28T16:06:38.507+0000] {local_task_job_runner.py:120} INFO - ::group::Pre task execution logs
[2024-12-28T16:06:38.545+0000] {taskinstance.py:2076} INFO - Dependencies all met for dep_context=non-requeueable deps ti=<TaskInstance: pipeline.insert_data_into_data_warehouse manual__2024-12-28T16:06:04.832581+00:00 [queued]>
[2024-12-28T16:06:38.557+0000] {taskinstance.py:2076} INFO - Dependencies all met for dep_context=requeueable deps ti=<TaskInstance: pipeline.insert_data_into_data_warehouse manual__2024-12-28T16:06:04.832581+00:00 [queued]>
[2024-12-28T16:06:38.558+0000] {taskinstance.py:2306} INFO - Starting attempt 1 of 1
[2024-12-28T16:06:38.574+0000] {taskinstance.py:2330} INFO - Executing <Task(_PythonDecoratedOperator): insert_data_into_data_warehouse> on 2024-12-28 16:06:04.832581+00:00
[2024-12-28T16:06:38.580+0000] {standard_task_runner.py:64} INFO - Started process 421 to run task
[2024-12-28T16:06:38.584+0000] {standard_task_runner.py:90} INFO - Running: ['***', 'tasks', 'run', 'pipeline', 'insert_data_into_data_warehouse', 'manual__2024-12-28T16:06:04.832581+00:00', '--job-id', '1082', '--raw', '--subdir', 'DAGS_FOLDER/pipline.py', '--cfg-path', '/tmp/tmpw7h1nhic']
[2024-12-28T16:06:38.587+0000] {standard_task_runner.py:91} INFO - Job 1082: Subtask insert_data_into_data_warehouse
[2024-12-28T16:06:38.645+0000] {task_command.py:426} INFO - Running <TaskInstance: pipeline.insert_data_into_data_warehouse manual__2024-12-28T16:06:04.832581+00:00 [running]> on host 7f22350fc6f3
[2024-12-28T16:06:38.763+0000] {taskinstance.py:2648} INFO - Exporting env vars: AIRFLOW_CTX_DAG_OWNER='***' AIRFLOW_CTX_DAG_ID='pipeline' AIRFLOW_CTX_TASK_ID='insert_data_into_data_warehouse' AIRFLOW_CTX_EXECUTION_DATE='2024-12-28T16:06:04.832581+00:00' AIRFLOW_CTX_TRY_NUMBER='1' AIRFLOW_CTX_DAG_RUN_ID='manual__2024-12-28T16:06:04.832581+00:00'
[2024-12-28T16:06:38.765+0000] {taskinstance.py:430} INFO - ::endgroup::
[2024-12-28T16:06:38.766+0000] {logging_mixin.py:188} INFO - None
[2024-12-28T16:06:38.766+0000] {taskinstance.py:441} INFO - ::group::Post task execution logs
[2024-12-28T16:06:38.767+0000] {taskinstance.py:2905} ERROR - Task failed with exception
Traceback (most recent call last):
  File "/home/airflow/.local/lib/python3.11/site-packages/airflow/models/taskinstance.py", line 465, in _execute_task
    result = _execute_callable(context=context, **execute_callable_kwargs)
             ^^^^^^^^^^^^^^^^^^^^^^^^^^^^^^^^^^^^^^^^^^^^^^^^^^^^^^^^^^^^^
  File "/home/airflow/.local/lib/python3.11/site-packages/airflow/models/taskinstance.py", line 432, in _execute_callable
    return execute_callable(context=context, **execute_callable_kwargs)
           ^^^^^^^^^^^^^^^^^^^^^^^^^^^^^^^^^^^^^^^^^^^^^^^^^^^^^^^^^^^^
  File "/home/airflow/.local/lib/python3.11/site-packages/airflow/models/baseoperator.py", line 401, in wrapper
    return func(self, *args, **kwargs)
           ^^^^^^^^^^^^^^^^^^^^^^^^^^^
  File "/home/airflow/.local/lib/python3.11/site-packages/airflow/decorators/base.py", line 265, in execute
    return_value = super().execute(context)
                   ^^^^^^^^^^^^^^^^^^^^^^^^
  File "/home/airflow/.local/lib/python3.11/site-packages/airflow/models/baseoperator.py", line 401, in wrapper
    return func(self, *args, **kwargs)
           ^^^^^^^^^^^^^^^^^^^^^^^^^^^
  File "/home/airflow/.local/lib/python3.11/site-packages/airflow/operators/python.py", line 235, in execute
    return_value = self.execute_callable()
                   ^^^^^^^^^^^^^^^^^^^^^^^
  File "/home/airflow/.local/lib/python3.11/site-packages/airflow/operators/python.py", line 252, in execute_callable
    return self.python_callable(*self.op_args, **self.op_kwargs)
           ^^^^^^^^^^^^^^^^^^^^^^^^^^^^^^^^^^^^^^^^^^^^^^^^^^^^^
  File "/opt/airflow/dags/pipline.py", line 382, in insert_data_into_data_warehouse
    data = verify_and_convert_structure(input)
           ^^^^^^^^^^^^^^^^^^^^^^^^^^^^^^^^^^^
  File "/opt/airflow/dags/pipline.py", line 24, in verify_and_convert_structure
    for idx, item in enumerate(t):
                     ^^^^^^^^^^^^
TypeError: 'NoneType' object is not iterable
[2024-12-28T16:06:38.784+0000] {taskinstance.py:1206} INFO - Marking task as FAILED. dag_id=pipeline, task_id=insert_data_into_data_warehouse, run_id=manual__2024-12-28T16:06:04.832581+00:00, execution_date=20241228T160604, start_date=20241228T160638, end_date=20241228T160638
[2024-12-28T16:06:38.807+0000] {standard_task_runner.py:110} ERROR - Failed to execute job 1082 for task insert_data_into_data_warehouse ('NoneType' object is not iterable; 421)
[2024-12-28T16:06:38.838+0000] {local_task_job_runner.py:243} INFO - Task exited with return code 1
[2024-12-28T16:06:38.858+0000] {taskinstance.py:3503} INFO - 0 downstream tasks scheduled from follow-on schedule check
[2024-12-28T16:06:38.861+0000] {local_task_job_runner.py:222} INFO - ::endgroup::
