[2024-11-10T01:52:16.620+0000] {local_task_job_runner.py:120} INFO - ::group::Pre task execution logs
[2024-11-10T01:52:16.643+0000] {taskinstance.py:2076} INFO - Dependencies all met for dep_context=non-requeueable deps ti=<TaskInstance: pipeline.fetch_data_from_postgres manual__2024-11-10T01:52:11.178566+00:00 [queued]>
[2024-11-10T01:52:16.650+0000] {taskinstance.py:2076} INFO - Dependencies all met for dep_context=requeueable deps ti=<TaskInstance: pipeline.fetch_data_from_postgres manual__2024-11-10T01:52:11.178566+00:00 [queued]>
[2024-11-10T01:52:16.651+0000] {taskinstance.py:2306} INFO - Starting attempt 1 of 1
[2024-11-10T01:52:16.664+0000] {taskinstance.py:2330} INFO - Executing <Task(_PythonDecoratedOperator): fetch_data_from_postgres> on 2024-11-10 01:52:11.178566+00:00
[2024-11-10T01:52:16.668+0000] {standard_task_runner.py:64} INFO - Started process 386 to run task
[2024-11-10T01:52:16.671+0000] {standard_task_runner.py:90} INFO - Running: ['***', 'tasks', 'run', 'pipeline', 'fetch_data_from_postgres', 'manual__2024-11-10T01:52:11.178566+00:00', '--job-id', '452', '--raw', '--subdir', 'DAGS_FOLDER/pipline.py', '--cfg-path', '/tmp/tmpv6v8a379']
[2024-11-10T01:52:16.673+0000] {standard_task_runner.py:91} INFO - Job 452: Subtask fetch_data_from_postgres
[2024-11-10T01:52:16.714+0000] {task_command.py:426} INFO - Running <TaskInstance: pipeline.fetch_data_from_postgres manual__2024-11-10T01:52:11.178566+00:00 [running]> on host f27d990d3764
[2024-11-10T01:52:16.794+0000] {taskinstance.py:2648} INFO - Exporting env vars: AIRFLOW_CTX_DAG_OWNER='***' AIRFLOW_CTX_DAG_ID='pipeline' AIRFLOW_CTX_TASK_ID='fetch_data_from_postgres' AIRFLOW_CTX_EXECUTION_DATE='2024-11-10T01:52:11.178566+00:00' AIRFLOW_CTX_TRY_NUMBER='1' AIRFLOW_CTX_DAG_RUN_ID='manual__2024-11-10T01:52:11.178566+00:00'
[2024-11-10T01:52:16.795+0000] {taskinstance.py:430} INFO - ::endgroup::
[2024-11-10T01:52:16.802+0000] {base.py:84} INFO - Using connection ID 'postgres_default' for task execution.
[2024-11-10T01:52:18.843+0000] {logging_mixin.py:188} INFO - Error connecting to PostgreSQL: connection to server at "host.docker.internal" (192.168.65.254), port 5433 failed: Connection refused
	Is the server running on that host and accepting TCP/IP connections?
[2024-11-10T01:52:18.844+0000] {python.py:237} INFO - Done. Returned value was: None
[2024-11-10T01:52:18.844+0000] {taskinstance.py:441} INFO - ::group::Post task execution logs
[2024-11-10T01:52:18.852+0000] {taskinstance.py:1206} INFO - Marking task as SUCCESS. dag_id=pipeline, task_id=fetch_data_from_postgres, run_id=manual__2024-11-10T01:52:11.178566+00:00, execution_date=20241110T015211, start_date=20241110T015216, end_date=20241110T015218
[2024-11-10T01:52:18.890+0000] {local_task_job_runner.py:243} INFO - Task exited with return code 0
[2024-11-10T01:52:18.911+0000] {taskinstance.py:3503} INFO - 1 downstream tasks scheduled from follow-on schedule check
[2024-11-10T01:52:18.914+0000] {local_task_job_runner.py:222} INFO - ::endgroup::
