[2024-12-27T00:00:33.908+0000] {local_task_job_runner.py:120} INFO - ::group::Pre task execution logs
[2024-12-27T00:00:33.930+0000] {taskinstance.py:2076} INFO - Dependencies all met for dep_context=non-requeueable deps ti=<TaskInstance: pipeline.insert_data_into_data_warehouse scheduled__2024-12-26T00:00:00+00:00 [queued]>
[2024-12-27T00:00:33.938+0000] {taskinstance.py:2076} INFO - Dependencies all met for dep_context=requeueable deps ti=<TaskInstance: pipeline.insert_data_into_data_warehouse scheduled__2024-12-26T00:00:00+00:00 [queued]>
[2024-12-27T00:00:33.938+0000] {taskinstance.py:2306} INFO - Starting attempt 1 of 1
[2024-12-27T00:00:33.949+0000] {taskinstance.py:2330} INFO - Executing <Task(_PythonDecoratedOperator): insert_data_into_data_warehouse> on 2024-12-26 00:00:00+00:00
[2024-12-27T00:00:33.953+0000] {standard_task_runner.py:64} INFO - Started process 21374 to run task
[2024-12-27T00:00:33.955+0000] {standard_task_runner.py:90} INFO - Running: ['***', 'tasks', 'run', 'pipeline', 'insert_data_into_data_warehouse', 'scheduled__2024-12-26T00:00:00+00:00', '--job-id', '1007', '--raw', '--subdir', 'DAGS_FOLDER/pipline.py', '--cfg-path', '/tmp/tmpbsjq98wp']
[2024-12-27T00:00:33.957+0000] {standard_task_runner.py:91} INFO - Job 1007: Subtask insert_data_into_data_warehouse
[2024-12-27T00:00:33.995+0000] {task_command.py:426} INFO - Running <TaskInstance: pipeline.insert_data_into_data_warehouse scheduled__2024-12-26T00:00:00+00:00 [running]> on host d021469cce5e
[2024-12-27T00:00:34.082+0000] {taskinstance.py:2648} INFO - Exporting env vars: AIRFLOW_CTX_DAG_OWNER='***' AIRFLOW_CTX_DAG_ID='pipeline' AIRFLOW_CTX_TASK_ID='insert_data_into_data_warehouse' AIRFLOW_CTX_EXECUTION_DATE='2024-12-26T00:00:00+00:00' AIRFLOW_CTX_TRY_NUMBER='1' AIRFLOW_CTX_DAG_RUN_ID='scheduled__2024-12-26T00:00:00+00:00'
[2024-12-27T00:00:34.083+0000] {taskinstance.py:430} INFO - ::endgroup::
[2024-12-27T00:00:34.084+0000] {logging_mixin.py:188} INFO - None
[2024-12-27T00:00:34.084+0000] {taskinstance.py:441} INFO - ::group::Post task execution logs
[2024-12-27T00:00:34.085+0000] {taskinstance.py:2905} ERROR - Task failed with exception
Traceback (most recent call last):
  File "/home/airflow/.local/lib/python3.11/site-packages/airflow/models/taskinstance.py", line 465, in _execute_task
    result = _execute_callable(context=context, **execute_callable_kwargs)
             ^^^^^^^^^^^^^^^^^^^^^^^^^^^^^^^^^^^^^^^^^^^^^^^^^^^^^^^^^^^^^
  File "/home/airflow/.local/lib/python3.11/site-packages/airflow/models/taskinstance.py", line 432, in _execute_callable
    return execute_callable(context=context, **execute_callable_kwargs)
           ^^^^^^^^^^^^^^^^^^^^^^^^^^^^^^^^^^^^^^^^^^^^^^^^^^^^^^^^^^^^
  File "/home/airflow/.local/lib/python3.11/site-packages/airflow/models/baseoperator.py", line 401, in wrapper
    return func(self, *args, **kwargs)
           ^^^^^^^^^^^^^^^^^^^^^^^^^^^
  File "/home/airflow/.local/lib/python3.11/site-packages/airflow/decorators/base.py", line 265, in execute
    return_value = super().execute(context)
                   ^^^^^^^^^^^^^^^^^^^^^^^^
  File "/home/airflow/.local/lib/python3.11/site-packages/airflow/models/baseoperator.py", line 401, in wrapper
    return func(self, *args, **kwargs)
           ^^^^^^^^^^^^^^^^^^^^^^^^^^^
  File "/home/airflow/.local/lib/python3.11/site-packages/airflow/operators/python.py", line 235, in execute
    return_value = self.execute_callable()
                   ^^^^^^^^^^^^^^^^^^^^^^^
  File "/home/airflow/.local/lib/python3.11/site-packages/airflow/operators/python.py", line 252, in execute_callable
    return self.python_callable(*self.op_args, **self.op_kwargs)
           ^^^^^^^^^^^^^^^^^^^^^^^^^^^^^^^^^^^^^^^^^^^^^^^^^^^^^
  File "/opt/airflow/dags/pipline.py", line 367, in insert_data_into_data_warehouse
    data = verify_and_convert_structure(input)
           ^^^^^^^^^^^^^^^^^^^^^^^^^^^^^^^^^^^
  File "/opt/airflow/dags/pipline.py", line 24, in verify_and_convert_structure
    for idx, item in enumerate(t):
                     ^^^^^^^^^^^^
TypeError: 'NoneType' object is not iterable
[2024-12-27T00:00:34.096+0000] {taskinstance.py:1206} INFO - Marking task as FAILED. dag_id=pipeline, task_id=insert_data_into_data_warehouse, run_id=scheduled__2024-12-26T00:00:00+00:00, execution_date=20241226T000000, start_date=20241227T000033, end_date=20241227T000034
[2024-12-27T00:00:34.110+0000] {standard_task_runner.py:110} ERROR - Failed to execute job 1007 for task insert_data_into_data_warehouse ('NoneType' object is not iterable; 21374)
[2024-12-27T00:00:34.127+0000] {local_task_job_runner.py:243} INFO - Task exited with return code 1
[2024-12-27T00:00:34.141+0000] {taskinstance.py:3503} INFO - 0 downstream tasks scheduled from follow-on schedule check
[2024-12-27T00:00:34.143+0000] {local_task_job_runner.py:222} INFO - ::endgroup::
